Workbook

Sheet Securities
B1: FUND INFO | U1: CATEGORY METRICS | AC1: PEER GROUP METRICS | AJ1: RETURNS | AQ1: CATEGORY RETURNS | AX1: CATEGORY RETURN RANK | BE1: CATEGORY SIZE | BL1: PEER GROUP RETURNS | BS1: PEER GROUP RETURN RANK | BZ1: PEER GROUP SIZE
B2: security_id | C2: security_name | D2: detailed_security_type | E2: investment_strategy | F2: fund_family | G2: fund_company_name | H2: broad_category_group | I2: broad_asset_class | J2: category_name | K2: category_index | L2: peer_group_name | M2: ycharts_benchmark_category | N2: inception_date_generic | O2: assets_under_management | P2: expense_ratio_generic | Q2: expense_ratio_rank | R2: expense_ratio_peer_group_rank | S2: max_manager_tenure | T2: discount_or_premium_to_nav | U2: alpha_rank | V2: information_ratio_rank | W2: sharpe_rank | X2: alpha_3y_vs_category | Y2: information_ratio_3y_vs_category | Z2: historical_sharpe_3y | AA2: rsquared_3y_vs_category | AB2: upside_downside_5y_vs_category | AC2: alpha_peer_group_rank | AD2: information_ratio_peer_group_rank | AE2: sharpe_peer_group_rank | AF2: market_alpha_3y_vs_pg | AG2: information_ratio_3y_vs_pg | AH2: rsquared_3y_vs_pg | AI2: upside_downside_5y_vs_pg | AJ2: one_month_total_return_nav | AK2: three_month_total_return_nav | AL2: ytd_total_return_nav | AM2: one_year_total_return_nav | AN2: annualized_three_year_total_return_nav | AO2: annualized_five_year_total_return_nav | AP2: annualized_ten_year_total_return_nav | AQ2: category_one_month_total_return | AR2: category_three_month_total_return | AS2: category_ytd_total_return | AT2: category_one_year_total_return | AU2: category_three_year_total_return | AV2: category_five_year_total_return | AW2: category_ten_year_total_return | AX2: one_month_total_return_rank_nav | AY2: three_month_total_return_rank_nav | AZ2: ytd_total_return_rank_nav | BA2: one_year_total_return_rank_nav | BB2: three_year_total_return_rank_nav | BC2: five_year_total_return_rank_nav | BD2: ten_year_total_return_rank_nav | BE2: one_month_total_return_rank_category_size_nav | BF2: three_month_total_return_rank_category_size_nav | BG2: ytd_total_return_rank_category_size_nav | BH2: one_year_total_return_rank_category_size_nav | BI2: three_year_total_return_rank_category_size_nav | BJ2: five_year_total_return_rank_category_size_nav | BK2: ten_year_total_return_rank_category_size_nav | BL2: peer_group_one_month_total_return | BM2: peer_group_three_month_total_return | BN2: peer_group_ytd_total_return | BO2: peer_group_one_year_total_return | BP2: peer_group_three_year_total_return | BQ2: peer_group_five_year_total_return | BR2: peer_group_ten_year_total_return | BS2: one_month_total_return_peer_group_rank_nav | BT2: three_month_total_return_peer_group_rank_nav | BU2: ytd_total_return_peer_group_rank_nav | BV2: one_year_total_return_peer_group_rank_nav | BW2: three_year_total_return_peer_group_rank_nav | BX2: five_year_total_return_peer_group_rank_nav | BY2: ten_year_total_return_peer_group_rank_nav | BZ2: one_month_total_return_peer_group_size_nav | CA2: three_month_total_return_peer_group_size_nav | CB2: ytd_total_return_peer_group_size_nav | CC2: one_year_total_return_peer_group_size_nav | CD2: three_year_total_return_peer_group_size_nav | CE2: five_year_total_return_peer_group_size_nav | CF2: ten_year_total_return_peer_group_size_nav
B3: M:APDFX | C3: {=_xll.YCI($B3,C$2)} -> Artisan High Income Fund Advisor | D3: {=_xll.YCI($B3,D$2)} -> mutual_fund | E3: {=_xll.YCI($B3,E$2)} -> The investment seeks to provide total return through a combination of current income and capital appreciation. Under normal circumstances, the fund will invest primarily in instruments that are rated, at the time of purchase, below investment grade (below BBB- by Standard & Poor's Rating Services ("S&P") or Fitch, Inc. ("Fitch") or below Baa3 by Moody's Investors Service, Inc. ("Moody's")), or comparably rated by another nationally recognized statistical rating organization ("NRSRO"), or unrated but determined by Artisan Partners to be of comparable quality. | F3: {=_xll.YCI($B3,F$2)} -> Artisan Partners Funds | G3: {=_xll.YCI($B3,G$2)} -> Artisan Partners Limited Partnership | H3: {=_xll.YCI($B3,H$2)} -> Fixed Income | I3: {=_xll.YCI($B3,I$2)} -> Taxable Bond | J3: {=_xll.YCI($B3,J$2)} -> High Yield Bond | ... N3: {=_xll.YCI($B3,N$2)} -> 2014-03-19 | O3: {=_xll.YCP($B3,O$2)} -> 4009299912 | P3: {=_xll.YCP($B3,P$2)} -> 0.008 | Q3: {=_xll.YCP($B3,Q$2)} -> 54 | R3: {=_xll.YCP($B3,R$2)} -> 56 | S3: {=_xll.YCP($B3,S$2)} -> 12.38 | T3: {=_xll.YCP($B3,T$2)} -> ERR: INVALID CALC | U3: {=_xll.YCP($B3,U$2)} -> 20 | V3: {=_xll.YCP($B3,V$2)} -> 38 | ... CF3: {=_xll.YCP($B3,CF$2)} -> 467
B4: AVDE | C4: {=_xll.YCI($B4,C$2)} -> Avantis International Equity ETF | D4: {=_xll.YCI($B4,D$2)} -> etf | E4: {=_xll.YCI($B4,E$2)} -> The investment seeks long-term capital appreciation. The fund invests primarily in a diverse group of non-U.S. companies across countries, market sectors and industry groups. It may invest in companies of all market capitalizations. Under normal market conditions, the fund will invest at least 80% of its assets in equity securities. It also may invest in derivative instruments such as futures contracts, currency forwards, and swap agreements. | F4: {=_xll.YCI($B4,F$2)} -> Avantis Investors | G4: {=_xll.YCI($B4,G$2)} -> American Century Investment Management Inc | H4: {=_xll.YCI($B4,H$2)} -> Equity | I4: {=_xll.YCI($B4,I$2)} -> International Equity | J4: {=_xll.YCI($B4,J$2)} -> Foreign Large Blend | ... N4: {=_xll.YCI($B4,N$2)} -> 2019-09-24 | O4: {=_xll.YCP($B4,O$2)} -> 18843246896 | P4: {=_xll.YCP($B4,P$2)} -> 0.0023 | Q4: {=_xll.YCP($B4,Q$2)} -> 14 | R4: {=_xll.YCP($B4,R$2)} -> 13 | S4: {=_xll.YCP($B4,S$2)} -> 6.86 | T4: {=_xll.YCP($B4,T$2)} -> 0.00176092 | U4: {=_xll.YCP($B4,U$2)} -> 14 | V4: {=_xll.YCP($B4,V$2)} -> 16 | ... CF4: {=_xll.YCP($B4,CF$2)} -> 164
B5: M:AVERX | C5: {=_xll.YCI($B5,C$2)} -> Ave Maria Value Focused Fund | D5: {=_xll.YCI($B5,D$2)} -> mutual_fund | E5: {=_xll.YCI($B5,E$2)} -> The investment seeks long-term capital appreciation. The fund invests at least 80% of its net assets, including the amount of any borrowings for investment purposes, in equity securities (which include common stocks, preferred stocks and securities convertible into common stocks). It may invest in the securities of companies of any size, regardless of market capitalization. The fund may also invest in exchange-traded funds ("ETFs") if the Adviser believes it is advisable to expose the fund to the broad market or to broad market sectors or to hedge against market risk without purchasing a large number of individual securities. The fund is non-diversified. | F5: {=_xll.YCI($B5,F$2)} -> Ave Maria Mutual Funds | G5: {=_xll.YCI($B5,G$2)} -> Schwartz Investment Counsel Inc | H5: {=_xll.YCI($B5,H$2)} -> Equity | I5: {=_xll.YCI($B5,I$2)} -> US Equity | J5: {=_xll.YCI($B5,J$2)} -> Mid-Cap Blend | ... N5: {=_xll.YCI($B5,N$2)} -> 1993-07-20 | O5: {=_xll.YCP($B5,O$2)} -> 132962126 | P5: {=_xll.YCP($B5,P$2)} -> 0.0113 | Q5: {=_xll.YCP($B5,Q$2)} -> 77 | R5: {=_xll.YCP($B5,R$2)} -> 71 | S5: {=_xll.YCP($B5,S$2)} -> 42.62 | T5: {=_xll.YCP($B5,T$2)} -> ERR: INVALID CALC | U5: {=_xll.YCP($B5,U$2)} -> 1 | V5: {=_xll.YCP($B5,V$2)} -> 5 | ... CF5: {=_xll.YCP($B5,CF$2)} -> 277
B6: AVIG | C6: {=_xll.YCI($B6,C$2)} -> Avantis Core Fixed Income ETF | D6: {=_xll.YCI($B6,D$2)} -> etf | E6: {=_xll.YCI($B6,E$2)} -> The investment seeks to maximize total return. The fund invests primarily in investment grade quality debt obligations from a diverse group of U.S. and non-U.S. issuers. Under normal market conditions, it will invest at least 80% of its net assets, plus any borrowings for investment purposes, in fixed income securities. The fund seeks to maintain a weighted average duration within 2 years of the weighted average duration of its benchmark, the Bloomberg U.S. Aggregate Bond index, as calculated by the manager. | F6: {=_xll.YCI($B6,F$2)} -> Avantis Investors | G6: {=_xll.YCI($B6,G$2)} -> American Century Investment Management Inc | H6: {=_xll.YCI($B6,H$2)} -> Fixed Income | I6: {=_xll.YCI($B6,I$2)} -> Taxable Bond | J6: {=_xll.YCI($B6,J$2)} -> Intermediate Core Bond | ... N6: {=_xll.YCI($B6,N$2)} -> 2020-10-13 | O6: {=_xll.YCP($B6,O$2)} -> 1980075978 | P6: {=_xll.YCP($B6,P$2)} -> 0.0015 | Q6: {=_xll.YCP($B6,Q$2)} -> 13 | R6: {=_xll.YCP($B6,R$2)} -> 8 | S6: {=_xll.YCP($B6,S$2)} -> 5.8 | T6: {=_xll.YCP($B6,T$2)} -> -5.645e-05 | U6: {=_xll.YCP($B6,U$2)} -> 20 | V6: {=_xll.YCP($B6,V$2)} -> 11 | ... CF6: {=_xll.YCP($B6,CF$2)} -> 24
B7: M:BIMIX | C7: {=_xll.YCI($B7,C$2)} -> Baird Intermediate Bond Fund Institutional | D7: {=_xll.YCI($B7,D$2)} -> mutual_fund | E7: {=_xll.YCI($B7,E$2)} -> The investment seeks an annual rate of total return, before fund expenses, greater than the annual rate of total return of the Bloomberg Intermediate U.S. government/Credit Index. The fund normally invests at least 80% of its net assets in the following types of U.S. dollar-denominated debt obligations: U.S. government and other public-sector agencies, asset-backed and mortgage-backed obligations of U.S. and foreign issuers and corporate debt of U.S. and foreign issuers. | F7: {=_xll.YCI($B7,F$2)} -> Baird | G7: {=_xll.YCI($B7,G$2)} -> Robert W. Baird & Co. Incorporated | H7: {=_xll.YCI($B7,H$2)} -> Fixed Income | I7: {=_xll.YCI($B7,I$2)} -> Taxable Bond | J7: {=_xll.YCI($B7,J$2)} -> Intermediate Core Bond | ... N7: {=_xll.YCI($B7,N$2)} -> 2000-09-29 | O7: {=_xll.YCP($B7,O$2)} -> 13133244822 | P7: {=_xll.YCP($B7,P$2)} -> 0.003 | Q7: {=_xll.YCP($B7,Q$2)} -> 33 | R7: {=_xll.YCP($B7,R$2)} -> 21 | S7: {=_xll.YCP($B7,S$2)} -> 25.85 | T7: {=_xll.YCP($B7,T$2)} -> ERR: INVALID CALC | U7: {=_xll.YCP($B7,U$2)} -> 13 | V7: {=_xll.YCP($B7,V$2)} -> 31 | ... CF7: {=_xll.YCP($B7,CF$2)} -> 154
B8: BIV | C8: {=_xll.YCI($B8,C$2)} -> Vanguard Intermediate-Term Bond Index Fund ETF | D8: {=_xll.YCI($B8,D$2)} -> etf | E8: {=_xll.YCI($B8,E$2)} -> The investment seeks to track the performance of the Bloomberg U.S. 5-10 Year Government/Credit Float Adjusted Index. This index includes all medium and larger issues of U.S. government, investment-grade corporate and investment-grade international dollar-denominated bonds that have maturities between 5 and 10 years and are publicly issued. All of the fund's investments will be selected through the sampling process, and at least 80% of its assets will be invested in bonds held in the index. | F8: {=_xll.YCI($B8,F$2)} -> Vanguard | G8: {=_xll.YCI($B8,G$2)} -> Vanguard Group, Inc. (via Vanguard Capital Mgmt) | H8: {=_xll.YCI($B8,H$2)} -> Fixed Income | I8: {=_xll.YCI($B8,I$2)} -> Taxable Bond | J8: {=_xll.YCI($B8,J$2)} -> Intermediate Core Bond | ... N8: {=_xll.YCI($B8,N$2)} -> 2007-04-03 | O8: {=_xll.YCP($B8,O$2)} -> 28797391268 | P8: {=_xll.YCP($B8,P$2)} -> 0.0003 | Q8: {=_xll.YCP($B8,Q$2)} -> 7 | R8: {=_xll.YCP($B8,R$2)} -> 4 | S8: {=_xll.YCP($B8,S$2)} -> 18.28 | T8: {=_xll.YCP($B8,T$2)} -> 0 | U8: {=_xll.YCP($B8,U$2)} -> 18 | V8: {=_xll.YCP($B8,V$2)} -> 16 | ... CF8: {=_xll.YCP($B8,CF$2)} -> 488
B9: M:BRXIX | C9: {=_xll.YCI($B9,C$2)} -> MFS Blended Research International Equity Fund I | D9: {=_xll.YCI($B9,D$2)} -> mutual_fund | E9: {=_xll.YCI($B9,E$2)} -> The investment seeks capital appreciation. The fund normally invests at least 80% of the fund's net assets in equity securities. Equity securities include common stocks and other securities that represent an ownership interest (or right to acquire an ownership interest) in a company or other issuer. MFS primarily invests in securities of companies with large capitalizations. MFS normally invests the fund's assets across different industries, sectors, countries, and regions, but MFS may invest a significant percentage of the fund's assets in issuers in a single industry, sector, country, or region. | F9: {=_xll.YCI($B9,F$2)} -> MFS | G9: {=_xll.YCI($B9,G$2)} -> Massachusetts Financial Services Company | H9: {=_xll.YCI($B9,H$2)} -> Equity | I9: {=_xll.YCI($B9,I$2)} -> International Equity | J9: {=_xll.YCI($B9,J$2)} -> Foreign Large Blend | ... N9: {=_xll.YCI($B9,N$2)} -> 2015-09-15 | O9: {=_xll.YCP($B9,O$2)} -> 4055533673 | P9: {=_xll.YCP($B9,P$2)} -> 0.0052 | Q9: {=_xll.YCP($B9,Q$2)} -> 37 | R9: {=_xll.YCP($B9,R$2)} -> 14 | S9: {=_xll.YCP($B9,S$2)} -> 10.88 | T9: {=_xll.YCP($B9,T$2)} -> ERR: INVALID CALC | U9: {=_xll.YCP($B9,U$2)} -> 2 | V9: {=_xll.YCP($B9,V$2)} -> 1 | ... CF9: {=_xll.YCP($B9,CF$2)} -> 129
B10: DFCF | C10: {=_xll.YCI($B10,C$2)} -> DFA Dimensional Core Fixed Income ETF | D10: {=_xll.YCI($B10,D$2)} -> etf | E10: {=_xll.YCI($B10,E$2)} -> The investment seeks to maximize total returns from the universe of eligible investments; Total return is comprised of income and capital appreciation. Under normal circumstances, at least 80% of the Portfolio’s net assets will be invested in fixed income securities considered to be investment grade quality. The Portfolio primarily invests in securities that mature within twenty years from the date of settlement. The Portfolio will generally maintain a weighted average duration of no more than one quarter year greater than, and no less than one year below, the weighted average duration of the Portfolio’s benchmark, the Bloomberg U.S. Aggregate Bond Index. | F10: {=_xll.YCI($B10,F$2)} -> Dimensional Fund Advisors | G10: {=_xll.YCI($B10,G$2)} -> Dimensional Fund Advisors LP | H10: {=_xll.YCI($B10,H$2)} -> Fixed Income | I10: {=_xll.YCI($B10,I$2)} -> Taxable Bond | J10: {=_xll.YCI($B10,J$2)} -> Intermediate Core Bond | ... N10: {=_xll.YCI($B10,N$2)} -> 2021-11-15 | O10: {=_xll.YCP($B10,O$2)} -> 10915181278 | P10: {=_xll.YCP($B10,P$2)} -> 0.0017 | Q10: {=_xll.YCP($B10,Q$2)} -> 14 | R10: {=_xll.YCP($B10,R$2)} -> 18 | S10: {=_xll.YCP($B10,S$2)} -> 4.71 | T10: {=_xll.YCP($B10,T$2)} -> 0.00048216 | U10: {=_xll.YCP($B10,U$2)} -> 12 | V10: {=_xll.YCP($B10,V$2)} -> 8 | ... CF10: {=_xll.YCP($B10,CF$2)} -> 210
B11: M:DHRIX | C11: {=_xll.YCI($B11,C$2)} -> Diamond Hill Core Bond Fund I | D11: {=_xll.YCI($B11,D$2)} -> mutual_fund | E11: {=_xll.YCI($B11,E$2)} -> The investment seeks to maximize total return consistent with the preservation of capital. The Advisor intends to provide total return by investing at least 80% of its net assets at the time of purchase in a diversified portfolio of investment grade, fixed income securities, including bonds, debt securities and other similar U.S. dollar-denominated instruments issued by various U.S. public- or private-sector entities, by non-U.S. corporations or U.S. affiliates of non-U.S. corporations, including those in emerging markets. | F11: {=_xll.YCI($B11,F$2)} -> Diamond Hill Funds | G11: {=_xll.YCI($B11,G$2)} -> Diamond Hill Capital Management, LLC | H11: {=_xll.YCI($B11,H$2)} -> Fixed Income | I11: {=_xll.YCI($B11,I$2)} -> Taxable Bond | J11: {=_xll.YCI($B11,J$2)} -> Intermediate Core Bond | ... N11: {=_xll.YCI($B11,N$2)} -> 2016-07-05 | O11: {=_xll.YCP($B11,O$2)} -> 2477684562 | P11: {=_xll.YCP($B11,P$2)} -> 0.0048 | Q11: {=_xll.YCP($B11,Q$2)} -> 59 | R11: {=_xll.YCP($B11,R$2)} -> 48 | S11: {=_xll.YCP($B11,S$2)} -> 10.08 | T11: {=_xll.YCP($B11,T$2)} -> ERR: INVALID CALC | U11: {=_xll.YCP($B11,U$2)} -> 9 | V11: {=_xll.YCP($B11,V$2)} -> 5 | ... CF11: {=_xll.YCP($B11,CF$2)} -> 488
B12: M:EICOX | C12: {=_xll.YCI($B12,C$2)} -> Eaton Vance Emerging and Frontier Countries Eq I | D12: {=_xll.YCI($B12,D$2)} -> mutual_fund | E12: {=_xll.YCI($B12,E$2)} -> The investment seeks total return. The fund seeks its investment objective by investing at least 80% of its net assets (plus the amount of any borrowings for investment purposes) in equity investments in emerging and frontier market countries. Emerging market countries are countries represented in the MSCI Emerging Markets Index. Equity investments include common stocks, preferred stocks, private equity securities and other instruments that provide exposure to equity securities or markets. The fund is non-diversified. | F12: {=_xll.YCI($B12,F$2)} -> Eaton Vance | G12: {=_xll.YCI($B12,G$2)} -> Boston Management and Research | H12: {=_xll.YCI($B12,H$2)} -> Equity | I12: {=_xll.YCI($B12,I$2)} -> International Equity | J12: {=_xll.YCI($B12,J$2)} -> Diversified Emerging Mkts | ... N12: {=_xll.YCI($B12,N$2)} -> 2013-11-01 | O12: {=_xll.YCP($B12,O$2)} -> 3971296779 | P12: {=_xll.YCP($B12,P$2)} -> 0.0115 | Q12: {=_xll.YCP($B12,Q$2)} -> 67 | R12: {=_xll.YCP($B12,R$2)} -> 36 | S12: {=_xll.YCP($B12,S$2)} -> 3.34 | T12: {=_xll.YCP($B12,T$2)} -> ERR: INVALID CALC | U12: {=_xll.YCP($B12,U$2)} -> 13 | V12: {=_xll.YCP($B12,V$2)} -> 14 | ... CF12: {=_xll.YCP($B12,CF$2)} -> 12
B13: EMMF | C13: {=_xll.YCI($B13,C$2)} -> WisdomTree Emerging Markets Multifactor Fund | D13: {=_xll.YCI($B13,D$2)} -> etf | E13: {=_xll.YCI($B13,E$2)} -> The investment seeks capital appreciation. The fund invests, under normal circumstances, at least 80% of its net assets, plus any borrowings for investment purposes, in securities of emerging markets issuers and/or investments that have economic characteristics that are substantially similar to the economic characteristics of such securities. The fund manager generally expects to invest in large- and mid-capitalization companies, but the fund may also invest in small-capitalization companies. It is non-diversified. | F13: {=_xll.YCI($B13,F$2)} -> WisdomTree | G13: {=_xll.YCI($B13,G$2)} -> WisdomTree Asset Management Inc | H13: {=_xll.YCI($B13,H$2)} -> Equity | I13: {=_xll.YCI($B13,I$2)} -> International Equity | J13: {=_xll.YCI($B13,J$2)} -> Diversified Emerging Mkts | ... N13: {=_xll.YCI($B13,N$2)} -> 2018-08-10 | O13: {=_xll.YCP($B13,O$2)} -> 181517157 | P13: {=_xll.YCP($B13,P$2)} -> 0.0048 | Q13: {=_xll.YCP($B13,Q$2)} -> 22 | R13: {=_xll.YCP($B13,R$2)} -> 14 | S13: {=_xll.YCP($B13,S$2)} -> 5.77 | T13: {=_xll.YCP($B13,T$2)} -> -0.00900941 | U13: {=_xll.YCP($B13,U$2)} -> 31 | V13: {=_xll.YCP($B13,V$2)} -> 58 | ... CF13: {=_xll.YCP($B13,CF$2)} -> 597
B14: EYLD | C14: {=_xll.YCI($B14,C$2)} -> Cambria Emerging Shareholder Yield ETF | D14: {=_xll.YCI($B14,D$2)} -> etf | E14: {=_xll.YCI($B14,E$2)} -> The investment seeks income and capital appreciation. The fund is actively managed and seeks to achieve its investment objective by investing, under normal market conditions, at least 80% of its total assets in equity securities, including common stock and depositary receipts, issued by publicly listed companies in emerging foreign markets that provide high "shareholder yield." Its investment adviser, Cambria Investment Management, L.P. ("Cambria" or the "Adviser"), defines "shareholder yield" as the totality of returns realized by an investor from a company’s cash payments for dividends, buybacks and debt paydowns. | F14: {=_xll.YCI($B14,F$2)} -> Cambria | G14: {=_xll.YCI($B14,G$2)} -> Cambria Investment Management, L.P. | H14: {=_xll.YCI($B14,H$2)} -> Equity | I14: {=_xll.YCI($B14,I$2)} -> International Equity | J14: {=_xll.YCI($B14,J$2)} -> Diversified Emerging Mkts | ... N14: {=_xll.YCI($B14,N$2)} -> 2016-07-14 | O14: {=_xll.YCP($B14,O$2)} -> 893585101 | P14: {=_xll.YCP($B14,P$2)} -> 0.0063 | Q14: {=_xll.YCP($B14,Q$2)} -> 25 | R14: {=_xll.YCP($B14,R$2)} -> 18 | S14: {=_xll.YCP($B14,S$2)} -> 10.06 | T14: {=_xll.YCP($B14,T$2)} -> -0.00513506 | U14: {=_xll.YCP($B14,U$2)} -> 11 | V14: {=_xll.YCP($B14,V$2)} -> 17 | ... CF14: {=_xll.YCP($B14,CF$2)} -> 597
... B44: XSMO | C44: {=_xll.YCI($B44,C$2)} -> Invesco S&P SmallCap Momentum ETF | D44: {=_xll.YCI($B44,D$2)} -> etf | E44: {=_xll.YCI($B44,E$2)} -> The investment seeks to track the investment results (before fees and expenses) of the S&P SmallCap 600 Momentum Index (the "underlying index"). The fund generally will invest at least 90% of its total assets in securities that comprise the underlying index. Strictly in accordance with its guidelines and mandated procedures, the index provider compiles, maintains and calculates the underlying index, which is composed of constituents of the S&P SmallCap 600® Index that have the highest "momentum score." | F44: {=_xll.YCI($B44,F$2)} -> Invesco | G44: {=_xll.YCI($B44,G$2)} -> Invesco Capital Management LLC | H44: {=_xll.YCI($B44,H$2)} -> Equity | I44: {=_xll.YCI($B44,I$2)} -> US Equity | J44: {=_xll.YCI($B44,J$2)} -> Small Blend | ... N44: {=_xll.YCI($B44,N$2)} -> 2005-03-03 | O44: {=_xll.YCP($B44,O$2)} -> 3084880065 | P44: {=_xll.YCP($B44,P$2)} -> 0.0035 | Q44: {=_xll.YCP($B44,Q$2)} -> 17 | R44: {=_xll.YCP($B44,R$2)} -> 11 | S44: {=_xll.YCP($B44,S$2)} -> 19.18 | T44: {=_xll.YCP($B44,T$2)} -> 0.00057006 | U44: {=_xll.YCP($B44,U$2)} -> 4 | V44: {=_xll.YCP($B44,V$2)} -> 3 | ... CF44: {=_xll.YCP($B44,CF$2)} -> 997
C45: {=_xll.YCI($B45,C$2)} | D45: {=_xll.YCI($B45,D$2)} | E45: {=_xll.YCI($B45,E$2)} | F45: {=_xll.YCI($B45,F$2)} | G45: {=_xll.YCI($B45,G$2)} | H45: {=_xll.YCI($B45,H$2)} | I45: {=_xll.YCI($B45,I$2)} | J45: {=_xll.YCI($B45,J$2)} | ... N45: {=_xll.YCI($B45,N$2)} | O45: {=_xll.YCP($B45,O$2)} | P45: {=_xll.YCP($B45,P$2)} | Q45: {=_xll.YCP($B45,Q$2)} | R45: {=_xll.YCP($B45,R$2)} | S45: {=_xll.YCP($B45,S$2)} | T45: {=_xll.YCP($B45,T$2)} | U45: {=_xll.YCP($B45,U$2)} | W45: {=_xll.YCP($B45,W$2)} | AA45: {=_xll.YCP($B45,AA$2)} | AB45: {=_xll.YCP($B45,AB$2)} | AC45: {=_xll.YCP($B45,AC$2)} | AE45: {=_xll.YCP($B45,AE$2)} | AH45: {=_xll.YCP($B45,AH$2)} | AI45: {=_xll.YCP($B45,AI$2)} | AJ45: {=_xll.YCP($B45,AJ$2)} | AK45: {=_xll.YCP($B45,AK$2)} | AL45: {=_xll.YCP($B45,AL$2)} | AM45: {=_xll.YCP($B45,AM$2)} | AN45: {=_xll.YCP($B45,AN$2)} | AO45: {=_xll.YCP($B45,AO$2)} | ... CF45: {=_xll.YCP($B45,CF$2)}
C46: {=_xll.YCI($B46,C$2)} | D46: {=_xll.YCI($B46,D$2)} | E46: {=_xll.YCI($B46,E$2)} | F46: {=_xll.YCI($B46,F$2)} | G46: {=_xll.YCI($B46,G$2)} | H46: {=_xll.YCI($B46,H$2)} | I46: {=_xll.YCI($B46,I$2)} | J46: {=_xll.YCI($B46,J$2)} | ... N46: {=_xll.YCI($B46,N$2)} | O46: {=_xll.YCP($B46,O$2)} | P46: {=_xll.YCP($B46,P$2)} | Q46: {=_xll.YCP($B46,Q$2)} | R46: {=_xll.YCP($B46,R$2)} | S46: {=_xll.YCP($B46,S$2)} | T46: {=_xll.YCP($B46,T$2)} | U46: {=_xll.YCP($B46,U$2)} | W46: {=_xll.YCP($B46,W$2)} | AA46: {=_xll.YCP($B46,AA$2)} | AB46: {=_xll.YCP($B46,AB$2)} | AC46: {=_xll.YCP($B46,AC$2)} | AE46: {=_xll.YCP($B46,AE$2)} | AH46: {=_xll.YCP($B46,AH$2)} | AI46: {=_xll.YCP($B46,AI$2)} | AJ46: {=_xll.YCP($B46,AJ$2)} | AK46: {=_xll.YCP($B46,AK$2)} | AL46: {=_xll.YCP($B46,AL$2)} | AM46: {=_xll.YCP($B46,AM$2)} | AN46: {=_xll.YCP($B46,AN$2)} | AO46: {=_xll.YCP($B46,AO$2)} | ... CF46: {=_xll.YCP($B46,CF$2)}
C47: {=_xll.YCI($B47,C$2)} | D47: {=_xll.YCI($B47,D$2)} | E47: {=_xll.YCI($B47,E$2)} | F47: {=_xll.YCI($B47,F$2)} | G47: {=_xll.YCI($B47,G$2)} | H47: {=_xll.YCI($B47,H$2)} | I47: {=_xll.YCI($B47,I$2)} | J47: {=_xll.YCI($B47,J$2)} | ... N47: {=_xll.YCI($B47,N$2)} | O47: {=_xll.YCP($B47,O$2)} | P47: {=_xll.YCP($B47,P$2)} | Q47: {=_xll.YCP($B47,Q$2)} | R47: {=_xll.YCP($B47,R$2)} | S47: {=_xll.YCP($B47,S$2)} | T47: {=_xll.YCP($B47,T$2)} | U47: {=_xll.YCP($B47,U$2)} | W47: {=_xll.YCP($B47,W$2)} | AA47: {=_xll.YCP($B47,AA$2)} | AB47: {=_xll.YCP($B47,AB$2)} | AC47: {=_xll.YCP($B47,AC$2)} | AE47: {=_xll.YCP($B47,AE$2)} | AH47: {=_xll.YCP($B47,AH$2)} | AI47: {=_xll.YCP($B47,AI$2)} | AJ47: {=_xll.YCP($B47,AJ$2)} | AK47: {=_xll.YCP($B47,AK$2)} | AL47: {=_xll.YCP($B47,AL$2)} | AM47: {=_xll.YCP($B47,AM$2)} | AN47: {=_xll.YCP($B47,AN$2)} | AO47: {=_xll.YCP($B47,AO$2)} | ... BR47: {=_xll.YCP($B47,BR$2)} | BT47: {=_xll.YCP($B47,BT$2)} | BU47: {=_xll.YCP($B47,BU$2)} | BV47: {=_xll.YCP($B47,BV$2)} | BW47: {=_xll.YCP($B47,BW$2)} | BX47: {=_xll.YCP($B47,BX$2)} | BY47: {=_xll.YCP($B47,BY$2)} | BZ47: {=_xll.YCP($B47,BZ$2)} | CA47: {=_xll.YCP($B47,CA$2)} | ... CF47: {=_xll.YCP($B47,CF$2)}
C48: {=_xll.YCI($B48,C$2)} | D48: {=_xll.YCI($B48,D$2)} | E48: {=_xll.YCI($B48,E$2)} | F48: {=_xll.YCI($B48,F$2)} | G48: {=_xll.YCI($B48,G$2)} | H48: {=_xll.YCI($B48,H$2)} | I48: {=_xll.YCI($B48,I$2)} | J48: {=_xll.YCI($B48,J$2)} | ... N48: {=_xll.YCI($B48,N$2)} | O48: {=_xll.YCP($B48,O$2)} | P48: {=_xll.YCP($B48,P$2)} | Q48: {=_xll.YCP($B48,Q$2)} | R48: {=_xll.YCP($B48,R$2)} | S48: {=_xll.YCP($B48,S$2)} | T48: {=_xll.YCP($B48,T$2)} | U48: {=_xll.YCP($B48,U$2)} | W48: {=_xll.YCP($B48,W$2)} | AA48: {=_xll.YCP($B48,AA$2)} | AB48: {=_xll.YCP($B48,AB$2)} | AC48: {=_xll.YCP($B48,AC$2)} | AE48: {=_xll.YCP($B48,AE$2)} | AH48: {=_xll.YCP($B48,AH$2)} | AI48: {=_xll.YCP($B48,AI$2)} | AJ48: {=_xll.YCP($B48,AJ$2)} | AK48: {=_xll.YCP($B48,AK$2)} | AL48: {=_xll.YCP($B48,AL$2)} | AM48: {=_xll.YCP($B48,AM$2)} | AN48: {=_xll.YCP($B48,AN$2)} | AO48: {=_xll.YCP($B48,AO$2)} | ... BR48: {=_xll.YCP($B48,BR$2)} | BT48: {=_xll.YCP($B48,BT$2)} | BU48: {=_xll.YCP($B48,BU$2)} | BV48: {=_xll.YCP($B48,BV$2)} | BW48: {=_xll.YCP($B48,BW$2)} | BX48: {=_xll.YCP($B48,BX$2)} | BY48: {=_xll.YCP($B48,BY$2)} | BZ48: {=_xll.YCP($B48,BZ$2)} | CA48: {=_xll.YCP($B48,CA$2)} | ... CF48: {=_xll.YCP($B48,CF$2)}
C49: {=_xll.YCI($B49,C$2)} | D49: {=_xll.YCI($B49,D$2)} | E49: {=_xll.YCI($B49,E$2)} | F49: {=_xll.YCI($B49,F$2)} | G49: {=_xll.YCI($B49,G$2)} | H49: {=_xll.YCI($B49,H$2)} | I49: {=_xll.YCI($B49,I$2)} | J49: {=_xll.YCI($B49,J$2)} | ... N49: {=_xll.YCI($B49,N$2)} | O49: {=_xll.YCP($B49,O$2)} | P49: {=_xll.YCP($B49,P$2)} | Q49: {=_xll.YCP($B49,Q$2)} | R49: {=_xll.YCP($B49,R$2)} | S49: {=_xll.YCP($B49,S$2)} | T49: {=_xll.YCP($B49,T$2)} | U49: {=_xll.YCP($B49,U$2)} | W49: {=_xll.YCP($B49,W$2)} | AA49: {=_xll.YCP($B49,AA$2)} | AB49: {=_xll.YCP($B49,AB$2)} | AC49: {=_xll.YCP($B49,AC$2)} | AE49: {=_xll.YCP($B49,AE$2)} | AH49: {=_xll.YCP($B49,AH$2)} | AI49: {=_xll.YCP($B49,AI$2)} | AJ49: {=_xll.YCP($B49,AJ$2)} | AK49: {=_xll.YCP($B49,AK$2)} | AL49: {=_xll.YCP($B49,AL$2)} | AM49: {=_xll.YCP($B49,AM$2)} | AN49: {=_xll.YCP($B49,AN$2)} | AO49: {=_xll.YCP($B49,AO$2)} | ... BR49: {=_xll.YCP($B49,BR$2)} | BT49: {=_xll.YCP($B49,BT$2)} | BU49: {=_xll.YCP($B49,BU$2)} | BV49: {=_xll.YCP($B49,BV$2)} | BW49: {=_xll.YCP($B49,BW$2)} | BX49: {=_xll.YCP($B49,BX$2)} | BY49: {=_xll.YCP($B49,BY$2)} | BZ49: {=_xll.YCP($B49,BZ$2)} | CA49: {=_xll.YCP($B49,CA$2)} | ... CF49: {=_xll.YCP($B49,CF$2)}
C50: {=_xll.YCI($B50,C$2)} | D50: {=_xll.YCI($B50,D$2)} | E50: {=_xll.YCI($B50,E$2)} | F50: {=_xll.YCI($B50,F$2)} | G50: {=_xll.YCI($B50,G$2)} | H50: {=_xll.YCI($B50,H$2)} | I50: {=_xll.YCI($B50,I$2)} | J50: {=_xll.YCI($B50,J$2)} | ... N50: {=_xll.YCI($B50,N$2)} | O50: {=_xll.YCP($B50,O$2)} | P50: {=_xll.YCP($B50,P$2)} | Q50: {=_xll.YCP($B50,Q$2)} | R50: {=_xll.YCP($B50,R$2)} | S50: {=_xll.YCP($B50,S$2)} | T50: {=_xll.YCP($B50,T$2)} | U50: {=_xll.YCP($B50,U$2)} | W50: {=_xll.YCP($B50,W$2)} | AA50: {=_xll.YCP($B50,AA$2)} | AB50: {=_xll.YCP($B50,AB$2)} | AC50: {=_xll.YCP($B50,AC$2)} | AE50: {=_xll.YCP($B50,AE$2)} | AH50: {=_xll.YCP($B50,AH$2)} | AI50: {=_xll.YCP($B50,AI$2)} | AJ50: {=_xll.YCP($B50,AJ$2)} | AK50: {=_xll.YCP($B50,AK$2)} | AL50: {=_xll.YCP($B50,AL$2)} | AM50: {=_xll.YCP($B50,AM$2)} | AN50: {=_xll.YCP($B50,AN$2)} | AO50: {=_xll.YCP($B50,AO$2)} | ... BR50: {=_xll.YCP($B50,BR$2)} | BT50: {=_xll.YCP($B50,BT$2)} | BU50: {=_xll.YCP($B50,BU$2)} | BV50: {=_xll.YCP($B50,BV$2)} | BW50: {=_xll.YCP($B50,BW$2)} | BX50: {=_xll.YCP($B50,BX$2)} | BY50: {=_xll.YCP($B50,BY$2)} | BZ50: {=_xll.YCP($B50,BZ$2)} | CA50: {=_xll.YCP($B50,CA$2)} | ... CF50: {=_xll.YCP($B50,CF$2)}
C51: {=_xll.YCI($B51,C$2)} | D51: {=_xll.YCI($B51,D$2)} | E51: {=_xll.YCI($B51,E$2)} | F51: {=_xll.YCI($B51,F$2)} | G51: {=_xll.YCI($B51,G$2)} | H51: {=_xll.YCI($B51,H$2)} | I51: {=_xll.YCI($B51,I$2)} | J51: {=_xll.YCI($B51,J$2)} | ... N51: {=_xll.YCI($B51,N$2)} | O51: {=_xll.YCP($B51,O$2)} | P51: {=_xll.YCP($B51,P$2)} | Q51: {=_xll.YCP($B51,Q$2)} | R51: {=_xll.YCP($B51,R$2)} | S51: {=_xll.YCP($B51,S$2)} | T51: {=_xll.YCP($B51,T$2)} | U51: {=_xll.YCP($B51,U$2)} | W51: {=_xll.YCP($B51,W$2)} | AA51: {=_xll.YCP($B51,AA$2)} | AB51: {=_xll.YCP($B51,AB$2)} | AC51: {=_xll.YCP($B51,AC$2)} | AE51: {=_xll.YCP($B51,AE$2)} | AH51: {=_xll.YCP($B51,AH$2)} | AI51: {=_xll.YCP($B51,AI$2)} | AJ51: {=_xll.YCP($B51,AJ$2)} | AK51: {=_xll.YCP($B51,AK$2)} | AL51: {=_xll.YCP($B51,AL$2)} | AM51: {=_xll.YCP($B51,AM$2)} | AN51: {=_xll.YCP($B51,AN$2)} | AO51: {=_xll.YCP($B51,AO$2)} | ... BR51: {=_xll.YCP($B51,BR$2)} | BT51: {=_xll.YCP($B51,BT$2)} | BU51: {=_xll.YCP($B51,BU$2)} | BV51: {=_xll.YCP($B51,BV$2)} | BW51: {=_xll.YCP($B51,BW$2)} | BX51: {=_xll.YCP($B51,BX$2)} | BY51: {=_xll.YCP($B51,BY$2)} | BZ51: {=_xll.YCP($B51,BZ$2)} | CA51: {=_xll.YCP($B51,CA$2)} | ... CF51: {=_xll.YCP($B51,CF$2)}
C52: {=_xll.YCI($B52,C$2)} | D52: {=_xll.YCI($B52,D$2)} | E52: {=_xll.YCI($B52,E$2)} | F52: {=_xll.YCI($B52,F$2)} | G52: {=_xll.YCI($B52,G$2)} | H52: {=_xll.YCI($B52,H$2)} | I52: {=_xll.YCI($B52,I$2)} | J52: {=_xll.YCI($B52,J$2)} | ... N52: {=_xll.YCI($B52,N$2)} | O52: {=_xll.YCP($B52,O$2)} | P52: {=_xll.YCP($B52,P$2)} | Q52: {=_xll.YCP($B52,Q$2)} | R52: {=_xll.YCP($B52,R$2)} | S52: {=_xll.YCP($B52,S$2)} | T52: {=_xll.YCP($B52,T$2)} | U52: {=_xll.YCP($B52,U$2)} | W52: {=_xll.YCP($B52,W$2)} | AA52: {=_xll.YCP($B52,AA$2)} | AB52: {=_xll.YCP($B52,AB$2)} | AC52: {=_xll.YCP($B52,AC$2)} | AE52: {=_xll.YCP($B52,AE$2)} | AH52: {=_xll.YCP($B52,AH$2)} | AI52: {=_xll.YCP($B52,AI$2)} | AJ52: {=_xll.YCP($B52,AJ$2)} | AK52: {=_xll.YCP($B52,AK$2)} | AL52: {=_xll.YCP($B52,AL$2)} | AM52: {=_xll.YCP($B52,AM$2)} | AN52: {=_xll.YCP($B52,AN$2)} | AO52: {=_xll.YCP($B52,AO$2)} | ... BR52: {=_xll.YCP($B52,BR$2)} | BT52: {=_xll.YCP($B52,BT$2)} | BU52: {=_xll.YCP($B52,BU$2)} | BV52: {=_xll.YCP($B52,BV$2)} | BW52: {=_xll.YCP($B52,BW$2)} | BX52: {=_xll.YCP($B52,BX$2)} | BY52: {=_xll.YCP($B52,BY$2)} | BZ52: {=_xll.YCP($B52,BZ$2)} | CA52: {=_xll.YCP($B52,CA$2)} | ... CF52: {=_xll.YCP($B52,CF$2)}
C53: {=_xll.YCI($B53,C$2)} | D53: {=_xll.YCI($B53,D$2)} | E53: {=_xll.YCI($B53,E$2)} | F53: {=_xll.YCI($B53,F$2)} | G53: {=_xll.YCI($B53,G$2)} | H53: {=_xll.YCI($B53,H$2)} | I53: {=_xll.YCI($B53,I$2)} | J53: {=_xll.YCI($B53,J$2)} | ... N53: {=_xll.YCI($B53,N$2)} | O53: {=_xll.YCP($B53,O$2)} | P53: {=_xll.YCP($B53,P$2)} | Q53: {=_xll.YCP($B53,Q$2)} | R53: {=_xll.YCP($B53,R$2)} | S53: {=_xll.YCP($B53,S$2)} | T53: {=_xll.YCP($B53,T$2)} | U53: {=_xll.YCP($B53,U$2)} | W53: {=_xll.YCP($B53,W$2)} | AA53: {=_xll.YCP($B53,AA$2)} | AB53: {=_xll.YCP($B53,AB$2)} | AC53: {=_xll.YCP($B53,AC$2)} | AE53: {=_xll.YCP($B53,AE$2)} | AH53: {=_xll.YCP($B53,AH$2)} | AI53: {=_xll.YCP($B53,AI$2)} | AJ53: {=_xll.YCP($B53,AJ$2)} | AK53: {=_xll.YCP($B53,AK$2)} | AL53: {=_xll.YCP($B53,AL$2)} | AM53: {=_xll.YCP($B53,AM$2)} | AN53: {=_xll.YCP($B53,AN$2)} | AO53: {=_xll.YCP($B53,AO$2)} | ... BR53: {=_xll.YCP($B53,BR$2)} | BT53: {=_xll.YCP($B53,BT$2)} | BU53: {=_xll.YCP($B53,BU$2)} | BV53: {=_xll.YCP($B53,BV$2)} | BW53: {=_xll.YCP($B53,BW$2)} | BX53: {=_xll.YCP($B53,BX$2)} | BY53: {=_xll.YCP($B53,BY$2)} | BZ53: {=_xll.YCP($B53,BZ$2)} | CA53: {=_xll.YCP($B53,CA$2)} | ... CF53: {=_xll.YCP($B53,CF$2)}
C54: {=_xll.YCI($B54,C$2)} | D54: {=_xll.YCI($B54,D$2)} | E54: {=_xll.YCI($B54,E$2)} | F54: {=_xll.YCI($B54,F$2)} | G54: {=_xll.YCI($B54,G$2)} | H54: {=_xll.YCI($B54,H$2)} | I54: {=_xll.YCI($B54,I$2)} | J54: {=_xll.YCI($B54,J$2)} | ... N54: {=_xll.YCI($B54,N$2)} | O54: {=_xll.YCP($B54,O$2)} | P54: {=_xll.YCP($B54,P$2)} | Q54: {=_xll.YCP($B54,Q$2)} | R54: {=_xll.YCP($B54,R$2)} | S54: {=_xll.YCP($B54,S$2)} | T54: {=_xll.YCP($B54,T$2)} | U54: {=_xll.YCP($B54,U$2)} | W54: {=_xll.YCP($B54,W$2)} | AA54: {=_xll.YCP($B54,AA$2)} | AB54: {=_xll.YCP($B54,AB$2)} | AC54: {=_xll.YCP($B54,AC$2)} | AE54: {=_xll.YCP($B54,AE$2)} | AH54: {=_xll.YCP($B54,AH$2)} | AI54: {=_xll.YCP($B54,AI$2)} | AJ54: {=_xll.YCP($B54,AJ$2)} | AK54: {=_xll.YCP($B54,AK$2)} | AL54: {=_xll.YCP($B54,AL$2)} | AM54: {=_xll.YCP($B54,AM$2)} | AN54: {=_xll.YCP($B54,AN$2)} | AO54: {=_xll.YCP($B54,AO$2)} | ... BR54: {=_xll.YCP($B54,BR$2)} | BT54: {=_xll.YCP($B54,BT$2)} | BU54: {=_xll.YCP($B54,BU$2)} | BV54: {=_xll.YCP($B54,BV$2)} | BW54: {=_xll.YCP($B54,BW$2)} | BX54: {=_xll.YCP($B54,BX$2)} | BY54: {=_xll.YCP($B54,BY$2)} | BZ54: {=_xll.YCP($B54,BZ$2)} | CA54: {=_xll.YCP($B54,CA$2)} | ... CF54: {=_xll.YCP($B54,CF$2)}
C55: {=_xll.YCI($B55,C$2)} | D55: {=_xll.YCI($B55,D$2)} | E55: {=_xll.YCI($B55,E$2)} | F55: {=_xll.YCI($B55,F$2)} | G55: {=_xll.YCI($B55,G$2)} | H55: {=_xll.YCI($B55,H$2)} | I55: {=_xll.YCI($B55,I$2)} | J55: {=_xll.YCI($B55,J$2)} | ... N55: {=_xll.YCI($B55,N$2)} | O55: {=_xll.YCP($B55,O$2)} | P55: {=_xll.YCP($B55,P$2)} | Q55: {=_xll.YCP($B55,Q$2)} | R55: {=_xll.YCP($B55,R$2)} | S55: {=_xll.YCP($B55,S$2)} | T55: {=_xll.YCP($B55,T$2)} | U55: {=_xll.YCP($B55,U$2)} | W55: {=_xll.YCP($B55,W$2)} | AA55: {=_xll.YCP($B55,AA$2)} | AB55: {=_xll.YCP($B55,AB$2)} | AC55: {=_xll.YCP($B55,AC$2)} | AE55: {=_xll.YCP($B55,AE$2)} | AH55: {=_xll.YCP($B55,AH$2)} | AI55: {=_xll.YCP($B55,AI$2)} | AJ55: {=_xll.YCP($B55,AJ$2)} | AK55: {=_xll.YCP($B55,AK$2)} | AL55: {=_xll.YCP($B55,AL$2)} | AM55: {=_xll.YCP($B55,AM$2)} | AN55: {=_xll.YCP($B55,AN$2)} | AO55: {=_xll.YCP($B55,AO$2)} | ... BR55: {=_xll.YCP($B55,BR$2)} | BT55: {=_xll.YCP($B55,BT$2)} | BU55: {=_xll.YCP($B55,BU$2)} | BV55: {=_xll.YCP($B55,BV$2)} | BW55: {=_xll.YCP($B55,BW$2)} | BX55: {=_xll.YCP($B55,BX$2)} | BY55: {=_xll.YCP($B55,BY$2)} | BZ55: {=_xll.YCP($B55,BZ$2)} | CA55: {=_xll.YCP($B55,CA$2)} | ... CF55: {=_xll.YCP($B55,CF$2)}
C56: {=_xll.YCI($B56,C$2)} | D56: {=_xll.YCI($B56,D$2)} | E56: {=_xll.YCI($B56,E$2)} | F56: {=_xll.YCI($B56,F$2)} | G56: {=_xll.YCI($B56,G$2)} | H56: {=_xll.YCI($B56,H$2)} | I56: {=_xll.YCI($B56,I$2)} | J56: {=_xll.YCI($B56,J$2)} | ... N56: {=_xll.YCI($B56,N$2)} | O56: {=_xll.YCP($B56,O$2)} | P56: {=_xll.YCP($B56,P$2)} | Q56: {=_xll.YCP($B56,Q$2)} | R56: {=_xll.YCP($B56,R$2)} | S56: {=_xll.YCP($B56,S$2)} | T56: {=_xll.YCP($B56,T$2)} | U56: {=_xll.YCP($B56,U$2)} | W56: {=_xll.YCP($B56,W$2)} | AA56: {=_xll.YCP($B56,AA$2)} | AB56: {=_xll.YCP($B56,AB$2)} | AC56: {=_xll.YCP($B56,AC$2)} | AE56: {=_xll.YCP($B56,AE$2)} | AH56: {=_xll.YCP($B56,AH$2)} | AI56: {=_xll.YCP($B56,AI$2)} | AJ56: {=_xll.YCP($B56,AJ$2)} | AK56: {=_xll.YCP($B56,AK$2)} | AL56: {=_xll.YCP($B56,AL$2)} | AM56: {=_xll.YCP($B56,AM$2)} | AN56: {=_xll.YCP($B56,AN$2)} | AO56: {=_xll.YCP($B56,AO$2)} | ... CF56: {=_xll.YCP($B56,CF$2)}
C57: {=_xll.YCI($B57,C$2)} | D57: {=_xll.YCI($B57,D$2)} | E57: {=_xll.YCI($B57,E$2)} | F57: {=_xll.YCI($B57,F$2)} | G57: {=_xll.YCI($B57,G$2)} | H57: {=_xll.YCI($B57,H$2)} | I57: {=_xll.YCI($B57,I$2)} | J57: {=_xll.YCI($B57,J$2)} | ... N57: {=_xll.YCI($B57,N$2)} | O57: {=_xll.YCP($B57,O$2)} | P57: {=_xll.YCP($B57,P$2)} | Q57: {=_xll.YCP($B57,Q$2)} | R57: {=_xll.YCP($B57,R$2)} | S57: {=_xll.YCP($B57,S$2)} | T57: {=_xll.YCP($B57,T$2)} | U57: {=_xll.YCP($B57,U$2)} | W57: {=_xll.YCP($B57,W$2)} | AA57: {=_xll.YCP($B57,AA$2)} | AB57: {=_xll.YCP($B57,AB$2)} | AC57: {=_xll.YCP($B57,AC$2)} | AE57: {=_xll.YCP($B57,AE$2)} | AH57: {=_xll.YCP($B57,AH$2)} | AI57: {=_xll.YCP($B57,AI$2)} | AJ57: {=_xll.YCP($B57,AJ$2)} | AK57: {=_xll.YCP($B57,AK$2)} | AL57: {=_xll.YCP($B57,AL$2)} | AM57: {=_xll.YCP($B57,AM$2)} | AN57: {=_xll.YCP($B57,AN$2)} | AO57: {=_xll.YCP($B57,AO$2)} | ... CF57: {=_xll.YCP($B57,CF$2)}
C58: {=_xll.YCI($B58,C$2)} | D58: {=_xll.YCI($B58,D$2)} | E58: {=_xll.YCI($B58,E$2)} | F58: {=_xll.YCI($B58,F$2)} | G58: {=_xll.YCI($B58,G$2)} | H58: {=_xll.YCI($B58,H$2)} | I58: {=_xll.YCI($B58,I$2)} | J58: {=_xll.YCI($B58,J$2)} | ... N58: {=_xll.YCI($B58,N$2)} | O58: {=_xll.YCP($B58,O$2)} | P58: {=_xll.YCP($B58,P$2)} | Q58: {=_xll.YCP($B58,Q$2)} | R58: {=_xll.YCP($B58,R$2)} | S58: {=_xll.YCP($B58,S$2)} | T58: {=_xll.YCP($B58,T$2)} | U58: {=_xll.YCP($B58,U$2)} | W58: {=_xll.YCP($B58,W$2)} | AA58: {=_xll.YCP($B58,AA$2)} | AB58: {=_xll.YCP($B58,AB$2)} | AC58: {=_xll.YCP($B58,AC$2)} | AE58: {=_xll.YCP($B58,AE$2)} | AH58: {=_xll.YCP($B58,AH$2)} | AI58: {=_xll.YCP($B58,AI$2)} | AJ58: {=_xll.YCP($B58,AJ$2)} | AK58: {=_xll.YCP($B58,AK$2)} | AL58: {=_xll.YCP($B58,AL$2)} | AM58: {=_xll.YCP($B58,AM$2)} | AN58: {=_xll.YCP($B58,AN$2)} | AO58: {=_xll.YCP($B58,AO$2)} | ... CF58: {=_xll.YCP($B58,CF$2)}
C59: {=_xll.YCI($B59,C$2)} | D59: {=_xll.YCI($B59,D$2)} | E59: {=_xll.YCI($B59,E$2)} | F59: {=_xll.YCI($B59,F$2)} | G59: {=_xll.YCI($B59,G$2)} | H59: {=_xll.YCI($B59,H$2)} | I59: {=_xll.YCI($B59,I$2)} | J59: {=_xll.YCI($B59,J$2)} | ... N59: {=_xll.YCI($B59,N$2)} | O59: {=_xll.YCP($B59,O$2)} | P59: {=_xll.YCP($B59,P$2)} | Q59: {=_xll.YCP($B59,Q$2)} | R59: {=_xll.YCP($B59,R$2)} | S59: {=_xll.YCP($B59,S$2)} | T59: {=_xll.YCP($B59,T$2)} | U59: {=_xll.YCP($B59,U$2)} | W59: {=_xll.YCP($B59,W$2)} | AA59: {=_xll.YCP($B59,AA$2)} | AB59: {=_xll.YCP($B59,AB$2)} | AC59: {=_xll.YCP($B59,AC$2)} | AE59: {=_xll.YCP($B59,AE$2)} | AH59: {=_xll.YCP($B59,AH$2)} | AI59: {=_xll.YCP($B59,AI$2)} | AJ59: {=_xll.YCP($B59,AJ$2)} | AK59: {=_xll.YCP($B59,AK$2)} | AL59: {=_xll.YCP($B59,AL$2)} | AM59: {=_xll.YCP($B59,AM$2)} | AN59: {=_xll.YCP($B59,AN$2)} | AO59: {=_xll.YCP($B59,AO$2)} | ... CF59: {=_xll.YCP($B59,CF$2)}
C60: {=_xll.YCI($B60,C$2)} | D60: {=_xll.YCI($B60,D$2)} | E60: {=_xll.YCI($B60,E$2)} | F60: {=_xll.YCI($B60,F$2)} | G60: {=_xll.YCI($B60,G$2)} | H60: {=_xll.YCI($B60,H$2)} | I60: {=_xll.YCI($B60,I$2)} | J60: {=_xll.YCI($B60,J$2)} | ... N60: {=_xll.YCI($B60,N$2)} | O60: {=_xll.YCP($B60,O$2)} | P60: {=_xll.YCP($B60,P$2)} | Q60: {=_xll.YCP($B60,Q$2)} | R60: {=_xll.YCP($B60,R$2)} | S60: {=_xll.YCP($B60,S$2)} | T60: {=_xll.YCP($B60,T$2)} | U60: {=_xll.YCP($B60,U$2)} | W60: {=_xll.YCP($B60,W$2)} | AA60: {=_xll.YCP($B60,AA$2)} | AB60: {=_xll.YCP($B60,AB$2)} | AC60: {=_xll.YCP($B60,AC$2)} | AE60: {=_xll.YCP($B60,AE$2)} | AH60: {=_xll.YCP($B60,AH$2)} | AI60: {=_xll.YCP($B60,AI$2)} | AJ60: {=_xll.YCP($B60,AJ$2)} | AK60: {=_xll.YCP($B60,AK$2)} | AL60: {=_xll.YCP($B60,AL$2)} | AM60: {=_xll.YCP($B60,AM$2)} | AN60: {=_xll.YCP($B60,AN$2)} | AO60: {=_xll.YCP($B60,AO$2)} | ... CF60: {=_xll.YCP($B60,CF$2)}
C61: {=_xll.YCI($B61,C$2)} | D61: {=_xll.YCI($B61,D$2)} | E61: {=_xll.YCI($B61,E$2)} | F61: {=_xll.YCI($B61,F$2)} | G61: {=_xll.YCI($B61,G$2)} | H61: {=_xll.YCI($B61,H$2)} | I61: {=_xll.YCI($B61,I$2)} | J61: {=_xll.YCI($B61,J$2)} | ... N61: {=_xll.YCI($B61,N$2)} | O61: {=_xll.YCP($B61,O$2)} | P61: {=_xll.YCP($B61,P$2)} | Q61: {=_xll.YCP($B61,Q$2)} | R61: {=_xll.YCP($B61,R$2)} | S61: {=_xll.YCP($B61,S$2)} | T61: {=_xll.YCP($B61,T$2)} | U61: {=_xll.YCP($B61,U$2)} | W61: {=_xll.YCP($B61,W$2)} | AA61: {=_xll.YCP($B61,AA$2)} | AB61: {=_xll.YCP($B61,AB$2)} | AC61: {=_xll.YCP($B61,AC$2)} | AE61: {=_xll.YCP($B61,AE$2)} | AH61: {=_xll.YCP($B61,AH$2)} | AI61: {=_xll.YCP($B61,AI$2)} | AJ61: {=_xll.YCP($B61,AJ$2)} | AK61: {=_xll.YCP($B61,AK$2)} | AL61: {=_xll.YCP($B61,AL$2)} | AM61: {=_xll.YCP($B61,AM$2)} | AN61: {=_xll.YCP($B61,AN$2)} | AO61: {=_xll.YCP($B61,AO$2)} | ... CF61: {=_xll.YCP($B61,CF$2)}
C62: {=_xll.YCI($B62,C$2)} | D62: {=_xll.YCI($B62,D$2)} | E62: {=_xll.YCI($B62,E$2)} | F62: {=_xll.YCI($B62,F$2)} | G62: {=_xll.YCI($B62,G$2)} | H62: {=_xll.YCI($B62,H$2)} | I62: {=_xll.YCI($B62,I$2)} | J62: {=_xll.YCI($B62,J$2)} | ... N62: {=_xll.YCI($B62,N$2)} | O62: {=_xll.YCP($B62,O$2)} | P62: {=_xll.YCP($B62,P$2)} | Q62: {=_xll.YCP($B62,Q$2)} | R62: {=_xll.YCP($B62,R$2)} | S62: {=_xll.YCP($B62,S$2)} | T62: {=_xll.YCP($B62,T$2)} | U62: {=_xll.YCP($B62,U$2)} | W62: {=_xll.YCP($B62,W$2)} | AA62: {=_xll.YCP($B62,AA$2)} | AB62: {=_xll.YCP($B62,AB$2)} | AC62: {=_xll.YCP($B62,AC$2)} | AE62: {=_xll.YCP($B62,AE$2)} | AH62: {=_xll.YCP($B62,AH$2)} | AI62: {=_xll.YCP($B62,AI$2)} | AJ62: {=_xll.YCP($B62,AJ$2)} | AK62: {=_xll.YCP($B62,AK$2)} | AL62: {=_xll.YCP($B62,AL$2)} | AM62: {=_xll.YCP($B62,AM$2)} | AN62: {=_xll.YCP($B62,AN$2)} | AO62: {=_xll.YCP($B62,AO$2)} | ... CF62: {=_xll.YCP($B62,CF$2)}
C63: {=_xll.YCI($B63,C$2)} | D63: {=_xll.YCI($B63,D$2)} | E63: {=_xll.YCI($B63,E$2)} | F63: {=_xll.YCI($B63,F$2)} | G63: {=_xll.YCI($B63,G$2)} | H63: {=_xll.YCI($B63,H$2)} | I63: {=_xll.YCI($B63,I$2)} | J63: {=_xll.YCI($B63,J$2)} | ... N63: {=_xll.YCI($B63,N$2)} | O63: {=_xll.YCP($B63,O$2)} | P63: {=_xll.YCP($B63,P$2)} | Q63: {=_xll.YCP($B63,Q$2)} | R63: {=_xll.YCP($B63,R$2)} | S63: {=_xll.YCP($B63,S$2)} | T63: {=_xll.YCP($B63,T$2)} | U63: {=_xll.YCP($B63,U$2)} | W63: {=_xll.YCP($B63,W$2)} | AA63: {=_xll.YCP($B63,AA$2)} | AB63: {=_xll.YCP($B63,AB$2)} | AC63: {=_xll.YCP($B63,AC$2)} | AE63: {=_xll.YCP($B63,AE$2)} | AH63: {=_xll.YCP($B63,AH$2)} | AI63: {=_xll.YCP($B63,AI$2)} | AJ63: {=_xll.YCP($B63,AJ$2)} | AK63: {=_xll.YCP($B63,AK$2)} | AL63: {=_xll.YCP($B63,AL$2)} | AM63: {=_xll.YCP($B63,AM$2)} | AN63: {=_xll.YCP($B63,AN$2)} | AO63: {=_xll.YCP($B63,AO$2)} | ... CF63: {=_xll.YCP($B63,CF$2)}
C64: {=_xll.YCI($B64,C$2)} | D64: {=_xll.YCI($B64,D$2)} | E64: {=_xll.YCI($B64,E$2)} | F64: {=_xll.YCI($B64,F$2)} | G64: {=_xll.YCI($B64,G$2)} | H64: {=_xll.YCI($B64,H$2)} | I64: {=_xll.YCI($B64,I$2)} | J64: {=_xll.YCI($B64,J$2)} | ... N64: {=_xll.YCI($B64,N$2)} | O64: {=_xll.YCP($B64,O$2)} | P64: {=_xll.YCP($B64,P$2)} | Q64: {=_xll.YCP($B64,Q$2)} | R64: {=_xll.YCP($B64,R$2)} | S64: {=_xll.YCP($B64,S$2)} | T64: {=_xll.YCP($B64,T$2)} | U64: {=_xll.YCP($B64,U$2)} | W64: {=_xll.YCP($B64,W$2)} | AA64: {=_xll.YCP($B64,AA$2)} | AB64: {=_xll.YCP($B64,AB$2)} | AC64: {=_xll.YCP($B64,AC$2)} | AE64: {=_xll.YCP($B64,AE$2)} | AH64: {=_xll.YCP($B64,AH$2)} | AI64: {=_xll.YCP($B64,AI$2)} | AJ64: {=_xll.YCP($B64,AJ$2)} | AK64: {=_xll.YCP($B64,AK$2)} | AL64: {=_xll.YCP($B64,AL$2)} | AM64: {=_xll.YCP($B64,AM$2)} | AN64: {=_xll.YCP($B64,AN$2)} | AO64: {=_xll.YCP($B64,AO$2)} | ... CF64: {=_xll.YCP($B64,CF$2)}
C65: {=_xll.YCI($B65,C$2)} | D65: {=_xll.YCI($B65,D$2)} | E65: {=_xll.YCI($B65,E$2)} | F65: {=_xll.YCI($B65,F$2)} | G65: {=_xll.YCI($B65,G$2)} | H65: {=_xll.YCI($B65,H$2)} | I65: {=_xll.YCI($B65,I$2)} | J65: {=_xll.YCI($B65,J$2)} | ... N65: {=_xll.YCI($B65,N$2)} | O65: {=_xll.YCP($B65,O$2)} | P65: {=_xll.YCP($B65,P$2)} | Q65: {=_xll.YCP($B65,Q$2)} | R65: {=_xll.YCP($B65,R$2)} | S65: {=_xll.YCP($B65,S$2)} | T65: {=_xll.YCP($B65,T$2)} | U65: {=_xll.YCP($B65,U$2)} | W65: {=_xll.YCP($B65,W$2)} | AA65: {=_xll.YCP($B65,AA$2)} | AB65: {=_xll.YCP($B65,AB$2)} | AC65: {=_xll.YCP($B65,AC$2)} | AE65: {=_xll.YCP($B65,AE$2)} | AH65: {=_xll.YCP($B65,AH$2)} | AI65: {=_xll.YCP($B65,AI$2)} | AJ65: {=_xll.YCP($B65,AJ$2)} | AK65: {=_xll.YCP($B65,AK$2)} | AL65: {=_xll.YCP($B65,AL$2)} | AM65: {=_xll.YCP($B65,AM$2)} | AN65: {=_xll.YCP($B65,AN$2)} | AO65: {=_xll.YCP($B65,AO$2)} | ... CF65: {=_xll.YCP($B65,CF$2)}
C66: {=_xll.YCI($B66,C$2)} | D66: {=_xll.YCI($B66,D$2)} | E66: {=_xll.YCI($B66,E$2)} | F66: {=_xll.YCI($B66,F$2)} | G66: {=_xll.YCI($B66,G$2)} | H66: {=_xll.YCI($B66,H$2)} | I66: {=_xll.YCI($B66,I$2)} | J66: {=_xll.YCI($B66,J$2)} | ... N66: {=_xll.YCI($B66,N$2)} | O66: {=_xll.YCP($B66,O$2)} | P66: {=_xll.YCP($B66,P$2)} | Q66: {=_xll.YCP($B66,Q$2)} | R66: {=_xll.YCP($B66,R$2)} | S66: {=_xll.YCP($B66,S$2)} | T66: {=_xll.YCP($B66,T$2)} | U66: {=_xll.YCP($B66,U$2)} | W66: {=_xll.YCP($B66,W$2)} | AA66: {=_xll.YCP($B66,AA$2)} | AB66: {=_xll.YCP($B66,AB$2)} | AC66: {=_xll.YCP($B66,AC$2)} | AE66: {=_xll.YCP($B66,AE$2)} | AH66: {=_xll.YCP($B66,AH$2)} | AI66: {=_xll.YCP($B66,AI$2)} | AJ66: {=_xll.YCP($B66,AJ$2)} | AK66: {=_xll.YCP($B66,AK$2)} | AL66: {=_xll.YCP($B66,AL$2)} | AM66: {=_xll.YCP($B66,AM$2)} | AN66: {=_xll.YCP($B66,AN$2)} | AO66: {=_xll.YCP($B66,AO$2)} | ... CF66: {=_xll.YCP($B66,CF$2)}
C67: {=_xll.YCI($B67,C$2)} | D67: {=_xll.YCI($B67,D$2)} | E67: {=_xll.YCI($B67,E$2)} | F67: {=_xll.YCI($B67,F$2)} | G67: {=_xll.YCI($B67,G$2)} | H67: {=_xll.YCI($B67,H$2)} | I67: {=_xll.YCI($B67,I$2)} | J67: {=_xll.YCI($B67,J$2)} | ... N67: {=_xll.YCI($B67,N$2)} | O67: {=_xll.YCP($B67,O$2)} | P67: {=_xll.YCP($B67,P$2)} | Q67: {=_xll.YCP($B67,Q$2)} | R67: {=_xll.YCP($B67,R$2)} | S67: {=_xll.YCP($B67,S$2)} | T67: {=_xll.YCP($B67,T$2)} | U67: {=_xll.YCP($B67,U$2)} | W67: {=_xll.YCP($B67,W$2)} | AA67: {=_xll.YCP($B67,AA$2)} | AB67: {=_xll.YCP($B67,AB$2)} | AC67: {=_xll.YCP($B67,AC$2)} | AE67: {=_xll.YCP($B67,AE$2)} | AH67: {=_xll.YCP($B67,AH$2)} | AI67: {=_xll.YCP($B67,AI$2)} | AJ67: {=_xll.YCP($B67,AJ$2)} | AK67: {=_xll.YCP($B67,AK$2)} | AL67: {=_xll.YCP($B67,AL$2)} | AM67: {=_xll.YCP($B67,AM$2)} | AN67: {=_xll.YCP($B67,AN$2)} | AO67: {=_xll.YCP($B67,AO$2)} | ... CF67: {=_xll.YCP($B67,CF$2)}
... C100: {=_xll.YCI($B100,C$2)} | D100: {=_xll.YCI($B100,D$2)} | E100: {=_xll.YCI($B100,E$2)} | F100: {=_xll.YCI($B100,F$2)} | G100: {=_xll.YCI($B100,G$2)} | H100: {=_xll.YCI($B100,H$2)} | I100: {=_xll.YCI($B100,I$2)} | J100: {=_xll.YCI($B100,J$2)} | ... N100: {=_xll.YCI($B100,N$2)} | O100: {=_xll.YCP($B100,O$2)} | P100: {=_xll.YCP($B100,P$2)} | Q100: {=_xll.YCP($B100,Q$2)} | R100: {=_xll.YCP($B100,R$2)} | S100: {=_xll.YCP($B100,S$2)} | T100: {=_xll.YCP($B100,T$2)} | U100: {=_xll.YCP($B100,U$2)} | W100: {=_xll.YCP($B100,W$2)} | AA100: {=_xll.YCP($B100,AA$2)} | AB100: {=_xll.YCP($B100,AB$2)} | AC100: {=_xll.YCP($B100,AC$2)} | AE100: {=_xll.YCP($B100,AE$2)} | AH100: {=_xll.YCP($B100,AH$2)} | AI100: {=_xll.YCP($B100,AI$2)} | AJ100: {=_xll.YCP($B100,AJ$2)} | AK100: {=_xll.YCP($B100,AK$2)} | AL100: {=_xll.YCP($B100,AL$2)} | AM100: {=_xll.YCP($B100,AM$2)} | AN100: {=_xll.YCP($B100,AN$2)} | AO100: {=_xll.YCP($B100,AO$2)} | ... CF100: {=_xll.YCP($B100,CF$2)}

Sheet Related
B2: related_securities
A3: =Securities!B3 -> M:APDFX | C3: security_name | D3: detailed_security_type | E3: investment_strategy | F3: fund_family | G3: fund_company_name | H3: broad_category_group | I3: broad_asset_class | J3: category_name | K3: category_index | L3: peer_group_name | M3: ycharts_benchmark_category | N3: inception_date_generic | O3: assets_under_management | P3: expense_ratio_generic | Q3: expense_ratio_rank | R3: expense_ratio_peer_group_rank | S3: max_manager_tenure | T3: discount_or_premium_to_nav | U3: alpha_rank | V3: information_ratio_rank | W3: sharpe_rank | X3: alpha_3y_vs_category | Y3: information_ratio_3y_vs_category | Z3: historical_sharpe_3y | AA3: rsquared_3y_vs_category | AB3: upside_downside_5y_vs_category | AC3: alpha_peer_group_rank | AD3: information_ratio_peer_group_rank | AE3: sharpe_peer_group_rank | AF3: market_alpha_3y_vs_pg | AG3: information_ratio_3y_vs_pg | AH3: rsquared_3y_vs_pg | AI3: upside_downside_5y_vs_pg | AJ3: one_month_total_return_nav | AK3: three_month_total_return_nav | AL3: ytd_total_return_nav | AM3: one_year_total_return_nav | AN3: annualized_three_year_total_return_nav | AO3: annualized_five_year_total_return_nav | AP3: annualized_ten_year_total_return_nav | AQ3: category_one_month_total_return | AR3: category_three_month_total_return | AS3: category_ytd_total_return | AT3: category_one_year_total_return | AU3: category_three_year_total_return | AV3: category_five_year_total_return | AW3: category_ten_year_total_return | AX3: one_month_total_return_rank_nav | AY3: three_month_total_return_rank_nav | AZ3: ytd_total_return_rank_nav | BA3: one_year_total_return_rank_nav | BB3: three_year_total_return_rank_nav | BC3: five_year_total_return_rank_nav | BD3: ten_year_total_return_rank_nav | BE3: one_month_total_return_rank_category_size_nav | BF3: three_month_total_return_rank_category_size_nav | BG3: ytd_total_return_rank_category_size_nav | BH3: one_year_total_return_rank_category_size_nav | BI3: three_year_total_return_rank_category_size_nav | BJ3: five_year_total_return_rank_category_size_nav | BK3: ten_year_total_return_rank_category_size_nav | BL3: peer_group_one_month_total_return | BM3: peer_group_three_month_total_return | BN3: peer_group_ytd_total_return | BO3: peer_group_one_year_total_return | BP3: peer_group_three_year_total_return | BQ3: peer_group_five_year_total_return | BR3: peer_group_ten_year_total_return | BS3: one_month_total_return_peer_group_rank_nav | BT3: three_month_total_return_peer_group_rank_nav | BU3: ytd_total_return_peer_group_rank_nav | BV3: one_year_total_return_peer_group_rank_nav | BW3: three_year_total_return_peer_group_rank_nav | BX3: five_year_total_return_peer_group_rank_nav | BY3: ten_year_total_return_peer_group_rank_nav | BZ3: one_month_total_return_peer_group_size_nav | CA3: three_month_total_return_peer_group_size_nav | CB3: ytd_total_return_peer_group_size_nav | CC3: one_year_total_return_peer_group_size_nav | CD3: three_year_total_return_peer_group_size_nav | CE3: five_year_total_return_peer_group_size_nav | CF3: ten_year_total_return_peer_group_size_nav
B4: {=_xll.YCI(A3,B2)} -> M:IPYAX | C4: {=_xll.YCI($B4,C$3)} -> Voya High Yield Portfolio Adviser | D4: {=_xll.YCI($B4,D$3)} -> insurance_fund | E4: {=_xll.YCI($B4,E$3)} -> The investment seeks to provide investors with a high level of current income and total return. Under normal circumstances, the fund invests at least 80% of its net assets (plus the amount of any borrowings for investment purposes) in a diversified portfolio of high-yield bonds. For purposes of this 80% policy, high-yield bonds include, without limitation, bonds, debt instruments, and other fixed income and income-producing debt instruments, of any kind, issued or guaranteed by governmental or private-sector entities that are rated below investment grade by one or more NRSRO or, if unrated, determined by the fund to be of comparable quality. | F4: {=_xll.YCI($B4,F$3)} -> Voya | G4: {=_xll.YCI($B4,G$3)} -> Voya Investments, LLC | H4: {=_xll.YCI($B4,H$3)} -> Fixed Income | I4: {=_xll.YCI($B4,I$3)} -> Taxable Bond | J4: {=_xll.YCI($B4,J$3)} -> High Yield Bond | ... N4: {=_xll.YCI($B4,N$3)} -> ERR: NO DATA | O4: {=_xll.YCP($B4,O$3)} -> 53323513 | P4: {=_xll.YCP($B4,P$3)} -> 0.011 | Q4: {=_xll.YCP($B4,Q$3)} -> 72 | R4: {=_xll.YCP($B4,R$3)} -> 80 | S4: {=_xll.YCP($B4,S$3)} -> 1.09 | T4: {=_xll.YCP($B4,T$3)} -> ERR: INVALID CALC | U4: {=_xll.YCP($B4,U$3)} -> 78 | V4: {=_xll.YCP($B4,V$3)} -> 68 | ... CF4: {=_xll.YCP($B4,CF$3)} -> 467
B5: M:AGDYX | C5: {=_xll.YCI($B5,C$3)} -> AB High Income Fund Advisor | D5: {=_xll.YCI($B5,D$3)} -> mutual_fund | E5: {=_xll.YCI($B5,E$3)} -> The investment seeks to maximize total returns from price appreciation and income. The fund pursues income opportunities from government, corporate, emerging market and high-yield sources. It has the flexibility to invest in a broad range of fixed-income securities in both developed and emerging market countries. The fund's investments may include U.S. and non-U.S. corporate debt securities and sovereign debt securities. It may invest, without limitation, in either U.S. Dollar-denominated or non-U.S. Dollar-denominated fixed-income securities. | F5: {=_xll.YCI($B5,F$3)} -> AllianceBernstein | G5: {=_xll.YCI($B5,G$3)} -> AllianceBernstein L.P. | H5: {=_xll.YCI($B5,H$3)} -> Fixed Income | I5: {=_xll.YCI($B5,I$3)} -> Taxable Bond | J5: {=_xll.YCI($B5,J$3)} -> High Yield Bond | ... N5: {=_xll.YCI($B5,N$3)} -> 1994-02-25 | O5: {=_xll.YCP($B5,O$3)} -> 2020716292 | P5: {=_xll.YCP($B5,P$3)} -> 0.0061 | Q5: {=_xll.YCP($B5,Q$3)} -> 32 | R5: {=_xll.YCP($B5,R$3)} -> 22 | S5: {=_xll.YCP($B5,S$3)} -> 20.76 | T5: {=_xll.YCP($B5,T$3)} -> ERR: INVALID CALC | U5: {=_xll.YCP($B5,U$3)} -> 10 | V5: {=_xll.YCP($B5,V$3)} -> 9 | ... CF5: {=_xll.YCP($B5,CF$3)} -> 63
B6: M:PAOPX | C6: {=_xll.YCI($B6,C$3)} -> T Rowe Price Credit Opportunities Fund Adv | D6: {=_xll.YCI($B6,D$3)} -> mutual_fund | E6: {=_xll.YCI($B6,E$3)} -> The investment seeks a combination of long-term capital appreciation and high income. The fund normally invests at least 80% of its net assets (plus any borrowings for investment purposes) in credit instruments and derivative instruments that are linked to,or provide investment exposure to, credit instruments. The fund may invest without limit in bonds that are rated below investment grade (below BBB or an equivalent rating) or are not rated by credit rating agencies, as well as bank loans and other instruments that are rated below investment grade or are not rated by credit rating agencies. | F6: {=_xll.YCI($B6,F$3)} -> T. Rowe Price | G6: {=_xll.YCI($B6,G$3)} -> T. Rowe Price Associates, Inc. | H6: {=_xll.YCI($B6,H$3)} -> Fixed Income | I6: {=_xll.YCI($B6,I$3)} -> Taxable Bond | J6: {=_xll.YCI($B6,J$3)} -> High Yield Bond | ... N6: {=_xll.YCI($B6,N$3)} -> 2014-04-29 | O6: {=_xll.YCP($B6,O$3)} -> 142735 | P6: {=_xll.YCP($B6,P$3)} -> 0.0091 | Q6: {=_xll.YCP($B6,Q$3)} -> 61 | R6: {=_xll.YCP($B6,R$3)} -> 66 | S6: {=_xll.YCP($B6,S$3)} -> 11.07 | T6: {=_xll.YCP($B6,T$3)} -> ERR: INVALID CALC | U6: {=_xll.YCP($B6,U$3)} -> 37 | V6: {=_xll.YCP($B6,V$3)} -> 56 | ... CF6: {=_xll.YCP($B6,CF$3)} -> 467
B7: M:PAHIX | C7: {=_xll.YCI($B7,C$3)} -> T Rowe Price High Yield Fund Advisor | D7: {=_xll.YCI($B7,D$3)} -> mutual_fund | E7: {=_xll.YCI($B7,E$3)} -> The investment seeks high current income and, secondarily, capital appreciation. The fund will normally invest at least 80% of its net assets in a widely diversified portfolio of high yield corporate bonds, often called "junk" bonds, as well as income-producing convertible securities and preferred stocks that are rated below investment grade or not rated by any major credit rating agency but deemed to be below investment grade. High yield bonds are rated below investment grade (BB and lower, or an equivalent rating), and tend to provide high income in an effort to compensate investors for their higher risk of default. | F7: {=_xll.YCI($B7,F$3)} -> T. Rowe Price | G7: {=_xll.YCI($B7,G$3)} -> T. Rowe Price Associates, Inc. | H7: {=_xll.YCI($B7,H$3)} -> Fixed Income | I7: {=_xll.YCI($B7,I$3)} -> Taxable Bond | J7: {=_xll.YCI($B7,J$3)} -> High Yield Bond | ... N7: {=_xll.YCI($B7,N$3)} -> 1984-12-31 | O7: {=_xll.YCP($B7,O$3)} -> 12285679 | P7: {=_xll.YCP($B7,P$3)} -> 0.0104 | Q7: {=_xll.YCP($B7,Q$3)} -> 71 | R7: {=_xll.YCP($B7,R$3)} -> 78 | S7: {=_xll.YCP($B7,S$3)} -> 7.55 | T7: {=_xll.YCP($B7,T$3)} -> ERR: INVALID CALC | U7: {=_xll.YCP($B7,U$3)} -> 58 | V7: {=_xll.YCP($B7,V$3)} -> 62 | ... CF7: {=_xll.YCP($B7,CF$3)} -> 467
B8: M:TUHAX | C8: {=_xll.YCI($B8,C$3)} -> T Rowe Price US High Yield Fund Advisor | D8: {=_xll.YCI($B8,D$3)} -> mutual_fund | E8: {=_xll.YCI($B8,E$3)} -> The investment seeks total return, and secondarily, current income. The fund normally invests at least 80% of its net assets (plus any borrowings for investment purposes) in U.S. high yield instruments. U.S. high yield instruments, commonly referred to as “junk” bonds, are debt instruments that are, at the time of purchase, rated below investment grade by a credit rating agency, or, if not rated by any credit rating agency, deemed by T. Rowe Price to be below investment grade. | F8: {=_xll.YCI($B8,F$3)} -> T. Rowe Price | G8: {=_xll.YCI($B8,G$3)} -> T. Rowe Price Associates, Inc. | H8: {=_xll.YCI($B8,H$3)} -> Fixed Income | I8: {=_xll.YCI($B8,I$3)} -> Taxable Bond | J8: {=_xll.YCI($B8,J$3)} -> High Yield Bond | ... N8: {=_xll.YCI($B8,N$3)} -> 2013-04-30 | O8: {=_xll.YCP($B8,O$3)} -> 2276524 | P8: {=_xll.YCP($B8,P$3)} -> 0.009 | Q8: {=_xll.YCP($B8,Q$3)} -> 60 | R8: {=_xll.YCP($B8,R$3)} -> 65 | S8: {=_xll.YCP($B8,S$3)} -> 13.26 | T8: {=_xll.YCP($B8,T$3)} -> ERR: INVALID CALC | U8: {=_xll.YCP($B8,U$3)} -> 64 | V8: {=_xll.YCP($B8,V$3)} -> 77 | ... CF8: {=_xll.YCP($B8,CF$3)} -> 467
C9: {=_xll.YCI($B9,C$3)} | D9: {=_xll.YCI($B9,D$3)} | E9: {=_xll.YCI($B9,E$3)} | F9: {=_xll.YCI($B9,F$3)} | G9: {=_xll.YCI($B9,G$3)} | H9: {=_xll.YCI($B9,H$3)} | I9: {=_xll.YCI($B9,I$3)} | J9: {=_xll.YCI($B9,J$3)} | ... N9: {=_xll.YCI($B9,N$3)} | O9: {=_xll.YCP($B9,O$3)} | P9: {=_xll.YCP($B9,P$3)} | Q9: {=_xll.YCP($B9,Q$3)} | R9: {=_xll.YCP($B9,R$3)} | S9: {=_xll.YCP($B9,S$3)} | T9: {=_xll.YCP($B9,T$3)} | U9: {=_xll.YCP($B9,U$3)} | V9: {=_xll.YCP($B9,V$3)} | ... CF9: {=_xll.YCP($B9,CF$3)}
A10: =Securities!B4 -> AVDE | C10: {=_xll.YCI($B10,C$3)} | D10: {=_xll.YCI($B10,D$3)} | E10: {=_xll.YCI($B10,E$3)} | F10: {=_xll.YCI($B10,F$3)} | G10: {=_xll.YCI($B10,G$3)} | H10: {=_xll.YCI($B10,H$3)} | I10: {=_xll.YCI($B10,I$3)} | J10: {=_xll.YCI($B10,J$3)} | ... N10: {=_xll.YCI($B10,N$3)} | O10: {=_xll.YCP($B10,O$3)} | P10: {=_xll.YCP($B10,P$3)} | Q10: {=_xll.YCP($B10,Q$3)} | R10: {=_xll.YCP($B10,R$3)} | S10: {=_xll.YCP($B10,S$3)} | T10: {=_xll.YCP($B10,T$3)} | U10: {=_xll.YCP($B10,U$3)} | V10: {=_xll.YCP($B10,V$3)} | ... CF10: {=_xll.YCP($B10,CF$3)}
B11: {=_xll.YCI(A10,B2)} -> DFAI | C11: {=_xll.YCI($B11,C$3)} -> DFA Dimensional International Core Equity Market | D11: {=_xll.YCI($B11,D$3)} -> etf | E11: {=_xll.YCI($B11,E$3)} -> The investment seeks to achieve long-term capital appreciation. The fund will invest in companies of all sizes, with increased exposure to smaller capitalization, lower relative price, and higher profitability companies as compared to their representation in the International Universe. As a non-fundamental policy, under normal circumstances, it will invest at least 80% of its net assets in equity securities. The Advisor may also increase or reduce the fund's exposure to an eligible company, or exclude a company, based on shorter-term considerations, such as a company's price momentum, short-run reversals, and investment characteristics. | F11: {=_xll.YCI($B11,F$3)} -> Dimensional Fund Advisors | G11: {=_xll.YCI($B11,G$3)} -> Dimensional Fund Advisors LP | H11: {=_xll.YCI($B11,H$3)} -> Equity | I11: {=_xll.YCI($B11,I$3)} -> International Equity | J11: {=_xll.YCI($B11,J$3)} -> Foreign Large Blend | ... N11: {=_xll.YCI($B11,N$3)} -> 2020-11-17 | O11: {=_xll.YCP($B11,O$3)} -> 18086159708 | P11: {=_xll.YCP($B11,P$3)} -> 0.0018 | Q11: {=_xll.YCP($B11,Q$3)} -> 9 | R11: {=_xll.YCP($B11,R$3)} -> 11 | S11: {=_xll.YCP($B11,S$3)} -> 5.71 | T11: {=_xll.YCP($B11,T$3)} -> -0.00232666 | U11: {=_xll.YCP($B11,U$3)} -> 21 | V11: {=_xll.YCP($B11,V$3)} -> 29 | ... CF11: {=_xll.YCP($B11,CF$3)} -> 164
B12: DFAX | C12: {=_xll.YCI($B12,C$3)} -> DFA Dimensional World ex US Core Equity 2 ETF | D12: {=_xll.YCI($B12,D$3)} -> etf | E12: {=_xll.YCI($B12,E$3)} -> The investment seeks to achieve long-term capital appreciation while considering federal tax implications of investment decisions. Generally, the Advisor buys and sells securities for the Portfolio with the goals of: (i) delaying and minimizing the realization of net capital gains (e.g., selling stocks with capital losses to offset gains, realized or anticipated); and (ii) maximizing the extent to which any realized net capital gains are long-term in nature (i.e., taxable at lower capital gains tax rates). The Portfolio is designed to purchase a broad and diverse group of equity securities of non‑U.S. companies in countries with developed and emerging markets. | F12: {=_xll.YCI($B12,F$3)} -> Dimensional Fund Advisors | G12: {=_xll.YCI($B12,G$3)} -> Dimensional Fund Advisors LP | H12: {=_xll.YCI($B12,H$3)} -> Equity | I12: {=_xll.YCI($B12,I$3)} -> International Equity | J12: {=_xll.YCI($B12,J$3)} -> Foreign Large Blend | ... N12: {=_xll.YCI($B12,N$3)} -> 2008-03-06 | O12: {=_xll.YCP($B12,O$3)} -> 12446043005 | P12: {=_xll.YCP($B12,P$3)} -> 0.0028 | Q12: {=_xll.YCP($B12,Q$3)} -> 20 | R12: {=_xll.YCP($B12,R$3)} -> 18 | S12: {=_xll.YCP($B12,S$3)} -> 16.43 | T12: {=_xll.YCP($B12,T$3)} -> -0.0042328 | U12: {=_xll.YCP($B12,U$3)} -> 25 | V12: {=_xll.YCP($B12,V$3)} -> 16 | ... CF12: {=_xll.YCP($B12,CF$3)} -> 164
